No error handlers are registered, logging exception.
Traceback (most recent call last):
  File "/Users/louisyeo18/telegram_portfolio_bot/venv/lib/python3.13/site-packages/telegram/ext/_application.py", line 1315, in process_update
    await coroutine
  File "/Users/louisyeo18/telegram_portfolio_bot/venv/lib/python3.13/site-packages/telegram/ext/_handlers/basehandler.py", line 159, in handle_update
    return await self.callback(update, context)
           ^^^^^^^^^^^^^^^^^^^^^^^^^^^^^^^^^^^^
  File "/Users/louisyeo18/telegram_portfolio_bot/bot.py", line 59, in button
    await query.answer()
  File "/Users/louisyeo18/telegram_portfolio_bot/venv/lib/python3.13/site-packages/telegram/_callbackquery.py", line 189, in answer
    return await self.get_bot().answer_callback_query(
           ^^^^^^^^^^^^^^^^^^^^^^^^^^^^^^^^^^^^^^^^^^^
    ...<10 lines>...
    )
    ^
  File "/Users/louisyeo18/telegram_portfolio_bot/venv/lib/python3.13/site-packages/telegram/ext/_extbot.py", line 972, in answer_callback_query
    return await super().answer_callback_query(
           ^^^^^^^^^^^^^^^^^^^^^^^^^^^^^^^^^^^^
    ...<10 lines>...
    )
    ^
  File "/Users/louisyeo18/telegram_portfolio_bot/venv/lib/python3.13/site-packages/telegram/_bot.py", line 4360, in answer_callback_query
    return await self._post(
           ^^^^^^^^^^^^^^^^^
    ...<7 lines>...
    )
    ^
  File "/Users/louisyeo18/telegram_portfolio_bot/venv/lib/python3.13/site-packages/telegram/_bot.py", line 703, in _post
    return await self._do_post(
           ^^^^^^^^^^^^^^^^^^^^
    ...<6 lines>...
    )
    ^
  File "/Users/louisyeo18/telegram_portfolio_bot/venv/lib/python3.13/site-packages/telegram/ext/_extbot.py", line 372, in _do_post
    return await super()._do_post(
           ^^^^^^^^^^^^^^^^^^^^^^^
    ...<6 lines>...
    )
    ^
  File "/Users/louisyeo18/telegram_portfolio_bot/venv/lib/python3.13/site-packages/telegram/_bot.py", line 732, in _do_post
    result = await request.post(
             ^^^^^^^^^^^^^^^^^^^
    ...<6 lines>...
    )
    ^
  File "/Users/louisyeo18/telegram_portfolio_bot/venv/lib/python3.13/site-packages/telegram/request/_baserequest.py", line 198, in post
    result = await self._request_wrapper(
             ^^^^^^^^^^^^^^^^^^^^^^^^^^^^
    ...<7 lines>...
    )
    ^
  File "/Users/louisyeo18/telegram_portfolio_bot/venv/lib/python3.13/site-packages/telegram/request/_baserequest.py", line 375, in _request_wrapper
    raise exception
telegram.error.BadRequest: Query is too old and response timeout expired or query id is invalid
No error handlers are registered, logging exception.
Traceback (most recent call last):
  File "/Users/louisyeo18/telegram_portfolio_bot/venv/lib/python3.13/site-packages/telegram/ext/_application.py", line 1315, in process_update
    await coroutine
  File "/Users/louisyeo18/telegram_portfolio_bot/venv/lib/python3.13/site-packages/telegram/ext/_handlers/basehandler.py", line 159, in handle_update
    return await self.callback(update, context)
           ^^^^^^^^^^^^^^^^^^^^^^^^^^^^^^^^^^^^
  File "/Users/louisyeo18/telegram_portfolio_bot/bot.py", line 59, in button
    await query.answer()
  File "/Users/louisyeo18/telegram_portfolio_bot/venv/lib/python3.13/site-packages/telegram/_callbackquery.py", line 189, in answer
    return await self.get_bot().answer_callback_query(
           ^^^^^^^^^^^^^^^^^^^^^^^^^^^^^^^^^^^^^^^^^^^
    ...<10 lines>...
    )
    ^
  File "/Users/louisyeo18/telegram_portfolio_bot/venv/lib/python3.13/site-packages/telegram/ext/_extbot.py", line 972, in answer_callback_query
    return await super().answer_callback_query(
           ^^^^^^^^^^^^^^^^^^^^^^^^^^^^^^^^^^^^
    ...<10 lines>...
    )
    ^
  File "/Users/louisyeo18/telegram_portfolio_bot/venv/lib/python3.13/site-packages/telegram/_bot.py", line 4360, in answer_callback_query
    return await self._post(
           ^^^^^^^^^^^^^^^^^
    ...<7 lines>...
    )
    ^
  File "/Users/louisyeo18/telegram_portfolio_bot/venv/lib/python3.13/site-packages/telegram/_bot.py", line 703, in _post
    return await self._do_post(
           ^^^^^^^^^^^^^^^^^^^^
    ...<6 lines>...
    )
    ^
  File "/Users/louisyeo18/telegram_portfolio_bot/venv/lib/python3.13/site-packages/telegram/ext/_extbot.py", line 372, in _do_post
    return await super()._do_post(
           ^^^^^^^^^^^^^^^^^^^^^^^
    ...<6 lines>...
    )
    ^
  File "/Users/louisyeo18/telegram_portfolio_bot/venv/lib/python3.13/site-packages/telegram/_bot.py", line 732, in _do_post
    result = await request.post(
             ^^^^^^^^^^^^^^^^^^^
    ...<6 lines>...
    )
    ^
  File "/Users/louisyeo18/telegram_portfolio_bot/venv/lib/python3.13/site-packages/telegram/request/_baserequest.py", line 198, in post
    result = await self._request_wrapper(
             ^^^^^^^^^^^^^^^^^^^^^^^^^^^^
    ...<7 lines>...
    )
    ^
  File "/Users/louisyeo18/telegram_portfolio_bot/venv/lib/python3.13/site-packages/telegram/request/_baserequest.py", line 375, in _request_wrapper
    raise exception
telegram.error.BadRequest: Query is too old and response timeout expired or query id is invalid
No error handlers are registered, logging exception.
Traceback (most recent call last):
  File "/Users/louisyeo18/telegram_portfolio_bot/venv/lib/python3.13/site-packages/telegram/ext/_application.py", line 1315, in process_update
    await coroutine
  File "/Users/louisyeo18/telegram_portfolio_bot/venv/lib/python3.13/site-packages/telegram/ext/_handlers/basehandler.py", line 159, in handle_update
    return await self.callback(update, context)
           ^^^^^^^^^^^^^^^^^^^^^^^^^^^^^^^^^^^^
  File "/Users/louisyeo18/telegram_portfolio_bot/bot.py", line 59, in button
    await query.answer()
  File "/Users/louisyeo18/telegram_portfolio_bot/venv/lib/python3.13/site-packages/telegram/_callbackquery.py", line 189, in answer
    return await self.get_bot().answer_callback_query(
           ^^^^^^^^^^^^^^^^^^^^^^^^^^^^^^^^^^^^^^^^^^^
    ...<10 lines>...
    )
    ^
  File "/Users/louisyeo18/telegram_portfolio_bot/venv/lib/python3.13/site-packages/telegram/ext/_extbot.py", line 972, in answer_callback_query
    return await super().answer_callback_query(
           ^^^^^^^^^^^^^^^^^^^^^^^^^^^^^^^^^^^^
    ...<10 lines>...
    )
    ^
  File "/Users/louisyeo18/telegram_portfolio_bot/venv/lib/python3.13/site-packages/telegram/_bot.py", line 4360, in answer_callback_query
    return await self._post(
           ^^^^^^^^^^^^^^^^^
    ...<7 lines>...
    )
    ^
  File "/Users/louisyeo18/telegram_portfolio_bot/venv/lib/python3.13/site-packages/telegram/_bot.py", line 703, in _post
    return await self._do_post(
           ^^^^^^^^^^^^^^^^^^^^
    ...<6 lines>...
    )
    ^
  File "/Users/louisyeo18/telegram_portfolio_bot/venv/lib/python3.13/site-packages/telegram/ext/_extbot.py", line 372, in _do_post
    return await super()._do_post(
           ^^^^^^^^^^^^^^^^^^^^^^^
    ...<6 lines>...
    )
    ^
  File "/Users/louisyeo18/telegram_portfolio_bot/venv/lib/python3.13/site-packages/telegram/_bot.py", line 732, in _do_post
    result = await request.post(
             ^^^^^^^^^^^^^^^^^^^
    ...<6 lines>...
    )
    ^
  File "/Users/louisyeo18/telegram_portfolio_bot/venv/lib/python3.13/site-packages/telegram/request/_baserequest.py", line 198, in post
    result = await self._request_wrapper(
             ^^^^^^^^^^^^^^^^^^^^^^^^^^^^
    ...<7 lines>...
    )
    ^
  File "/Users/louisyeo18/telegram_portfolio_bot/venv/lib/python3.13/site-packages/telegram/request/_baserequest.py", line 375, in _request_wrapper
    raise exception
telegram.error.BadRequest: Query is too old and response timeout expired or query id is invalid
No error handlers are registered, logging exception.
Traceback (most recent call last):
  File "/Users/louisyeo18/telegram_portfolio_bot/venv/lib/python3.13/site-packages/telegram/ext/_application.py", line 1315, in process_update
    await coroutine
  File "/Users/louisyeo18/telegram_portfolio_bot/venv/lib/python3.13/site-packages/telegram/ext/_handlers/basehandler.py", line 159, in handle_update
    return await self.callback(update, context)
           ^^^^^^^^^^^^^^^^^^^^^^^^^^^^^^^^^^^^
  File "/Users/louisyeo18/telegram_portfolio_bot/bot.py", line 59, in button
    await query.answer()
  File "/Users/louisyeo18/telegram_portfolio_bot/venv/lib/python3.13/site-packages/telegram/_callbackquery.py", line 189, in answer
    return await self.get_bot().answer_callback_query(
           ^^^^^^^^^^^^^^^^^^^^^^^^^^^^^^^^^^^^^^^^^^^
    ...<10 lines>...
    )
    ^
  File "/Users/louisyeo18/telegram_portfolio_bot/venv/lib/python3.13/site-packages/telegram/ext/_extbot.py", line 972, in answer_callback_query
    return await super().answer_callback_query(
           ^^^^^^^^^^^^^^^^^^^^^^^^^^^^^^^^^^^^
    ...<10 lines>...
    )
    ^
  File "/Users/louisyeo18/telegram_portfolio_bot/venv/lib/python3.13/site-packages/telegram/_bot.py", line 4360, in answer_callback_query
    return await self._post(
           ^^^^^^^^^^^^^^^^^
    ...<7 lines>...
    )
    ^
  File "/Users/louisyeo18/telegram_portfolio_bot/venv/lib/python3.13/site-packages/telegram/_bot.py", line 703, in _post
    return await self._do_post(
           ^^^^^^^^^^^^^^^^^^^^
    ...<6 lines>...
    )
    ^
  File "/Users/louisyeo18/telegram_portfolio_bot/venv/lib/python3.13/site-packages/telegram/ext/_extbot.py", line 372, in _do_post
    return await super()._do_post(
           ^^^^^^^^^^^^^^^^^^^^^^^
    ...<6 lines>...
    )
    ^
  File "/Users/louisyeo18/telegram_portfolio_bot/venv/lib/python3.13/site-packages/telegram/_bot.py", line 732, in _do_post
    result = await request.post(
             ^^^^^^^^^^^^^^^^^^^
    ...<6 lines>...
    )
    ^
  File "/Users/louisyeo18/telegram_portfolio_bot/venv/lib/python3.13/site-packages/telegram/request/_baserequest.py", line 198, in post
    result = await self._request_wrapper(
             ^^^^^^^^^^^^^^^^^^^^^^^^^^^^
    ...<7 lines>...
    )
    ^
  File "/Users/louisyeo18/telegram_portfolio_bot/venv/lib/python3.13/site-packages/telegram/request/_baserequest.py", line 375, in _request_wrapper
    raise exception
telegram.error.BadRequest: Query is too old and response timeout expired or query id is invalid
No error handlers are registered, logging exception.
Traceback (most recent call last):
  File "/Users/louisyeo18/telegram_portfolio_bot/venv/lib/python3.13/site-packages/telegram/ext/_application.py", line 1315, in process_update
    await coroutine
  File "/Users/louisyeo18/telegram_portfolio_bot/venv/lib/python3.13/site-packages/telegram/ext/_handlers/basehandler.py", line 159, in handle_update
    return await self.callback(update, context)
           ^^^^^^^^^^^^^^^^^^^^^^^^^^^^^^^^^^^^
  File "/Users/louisyeo18/telegram_portfolio_bot/bot.py", line 59, in button
    await query.answer()
  File "/Users/louisyeo18/telegram_portfolio_bot/venv/lib/python3.13/site-packages/telegram/_callbackquery.py", line 189, in answer
    return await self.get_bot().answer_callback_query(
           ^^^^^^^^^^^^^^^^^^^^^^^^^^^^^^^^^^^^^^^^^^^
    ...<10 lines>...
    )
    ^
  File "/Users/louisyeo18/telegram_portfolio_bot/venv/lib/python3.13/site-packages/telegram/ext/_extbot.py", line 972, in answer_callback_query
    return await super().answer_callback_query(
           ^^^^^^^^^^^^^^^^^^^^^^^^^^^^^^^^^^^^
    ...<10 lines>...
    )
    ^
  File "/Users/louisyeo18/telegram_portfolio_bot/venv/lib/python3.13/site-packages/telegram/_bot.py", line 4360, in answer_callback_query
    return await self._post(
           ^^^^^^^^^^^^^^^^^
    ...<7 lines>...
    )
    ^
  File "/Users/louisyeo18/telegram_portfolio_bot/venv/lib/python3.13/site-packages/telegram/_bot.py", line 703, in _post
    return await self._do_post(
           ^^^^^^^^^^^^^^^^^^^^
    ...<6 lines>...
    )
    ^
  File "/Users/louisyeo18/telegram_portfolio_bot/venv/lib/python3.13/site-packages/telegram/ext/_extbot.py", line 372, in _do_post
    return await super()._do_post(
           ^^^^^^^^^^^^^^^^^^^^^^^
    ...<6 lines>...
    )
    ^
  File "/Users/louisyeo18/telegram_portfolio_bot/venv/lib/python3.13/site-packages/telegram/_bot.py", line 732, in _do_post
    result = await request.post(
             ^^^^^^^^^^^^^^^^^^^
    ...<6 lines>...
    )
    ^
  File "/Users/louisyeo18/telegram_portfolio_bot/venv/lib/python3.13/site-packages/telegram/request/_baserequest.py", line 198, in post
    result = await self._request_wrapper(
             ^^^^^^^^^^^^^^^^^^^^^^^^^^^^
    ...<7 lines>...
    )
    ^
  File "/Users/louisyeo18/telegram_portfolio_bot/venv/lib/python3.13/site-packages/telegram/request/_baserequest.py", line 375, in _request_wrapper
    raise exception
telegram.error.BadRequest: Query is too old and response timeout expired or query id is invalid
No error handlers are registered, logging exception.
Traceback (most recent call last):
  File "/Users/louisyeo18/telegram_portfolio_bot/venv/lib/python3.13/site-packages/telegram/ext/_utils/networkloop.py", line 122, in network_retry_loop
    await do_action()
  File "/Users/louisyeo18/telegram_portfolio_bot/venv/lib/python3.13/site-packages/telegram/ext/_utils/networkloop.py", line 115, in do_action
    action_cb_task.result()
    ~~~~~~~~~~~~~~~~~~~~~^^
  File "/Users/louisyeo18/telegram_portfolio_bot/venv/lib/python3.13/site-packages/telegram/ext/_updater.py", line 340, in polling_action_cb
    updates = await self.bot.get_updates(
              ^^^^^^^^^^^^^^^^^^^^^^^^^^^
    ...<3 lines>...
    )
    ^
  File "/Users/louisyeo18/telegram_portfolio_bot/venv/lib/python3.13/site-packages/telegram/ext/_extbot.py", line 676, in get_updates
    updates = await super().get_updates(
              ^^^^^^^^^^^^^^^^^^^^^^^^^^
    ...<9 lines>...
    )
    ^
  File "/Users/louisyeo18/telegram_portfolio_bot/venv/lib/python3.13/site-packages/telegram/_bot.py", line 4780, in get_updates
    await self._post(
    ^^^^^^^^^^^^^^^^^
    ...<7 lines>...
    ),
    ^
  File "/Users/louisyeo18/telegram_portfolio_bot/venv/lib/python3.13/site-packages/telegram/_bot.py", line 703, in _post
    return await self._do_post(
           ^^^^^^^^^^^^^^^^^^^^
    ...<6 lines>...
    )
    ^
  File "/Users/louisyeo18/telegram_portfolio_bot/venv/lib/python3.13/site-packages/telegram/ext/_extbot.py", line 372, in _do_post
    return await super()._do_post(
           ^^^^^^^^^^^^^^^^^^^^^^^
    ...<6 lines>...
    )
    ^
  File "/Users/louisyeo18/telegram_portfolio_bot/venv/lib/python3.13/site-packages/telegram/_bot.py", line 732, in _do_post
    result = await request.post(
             ^^^^^^^^^^^^^^^^^^^
    ...<6 lines>...
    )
    ^
  File "/Users/louisyeo18/telegram_portfolio_bot/venv/lib/python3.13/site-packages/telegram/request/_baserequest.py", line 198, in post
    result = await self._request_wrapper(
             ^^^^^^^^^^^^^^^^^^^^^^^^^^^^
    ...<7 lines>...
    )
    ^
  File "/Users/louisyeo18/telegram_portfolio_bot/venv/lib/python3.13/site-packages/telegram/request/_baserequest.py", line 375, in _request_wrapper
    raise exception
telegram.error.Conflict: Conflict: terminated by other getUpdates request; make sure that only one bot instance is running
No error handlers are registered, logging exception.
Traceback (most recent call last):
  File "/Users/louisyeo18/telegram_portfolio_bot/venv/lib/python3.13/site-packages/telegram/ext/_utils/networkloop.py", line 122, in network_retry_loop
    await do_action()
  File "/Users/louisyeo18/telegram_portfolio_bot/venv/lib/python3.13/site-packages/telegram/ext/_utils/networkloop.py", line 115, in do_action
    action_cb_task.result()
    ~~~~~~~~~~~~~~~~~~~~~^^
  File "/Users/louisyeo18/telegram_portfolio_bot/venv/lib/python3.13/site-packages/telegram/ext/_updater.py", line 340, in polling_action_cb
    updates = await self.bot.get_updates(
              ^^^^^^^^^^^^^^^^^^^^^^^^^^^
    ...<3 lines>...
    )
    ^
  File "/Users/louisyeo18/telegram_portfolio_bot/venv/lib/python3.13/site-packages/telegram/ext/_extbot.py", line 676, in get_updates
    updates = await super().get_updates(
              ^^^^^^^^^^^^^^^^^^^^^^^^^^
    ...<9 lines>...
    )
    ^
  File "/Users/louisyeo18/telegram_portfolio_bot/venv/lib/python3.13/site-packages/telegram/_bot.py", line 4780, in get_updates
    await self._post(
    ^^^^^^^^^^^^^^^^^
    ...<7 lines>...
    ),
    ^
  File "/Users/louisyeo18/telegram_portfolio_bot/venv/lib/python3.13/site-packages/telegram/_bot.py", line 703, in _post
    return await self._do_post(
           ^^^^^^^^^^^^^^^^^^^^
    ...<6 lines>...
    )
    ^
  File "/Users/louisyeo18/telegram_portfolio_bot/venv/lib/python3.13/site-packages/telegram/ext/_extbot.py", line 372, in _do_post
    return await super()._do_post(
           ^^^^^^^^^^^^^^^^^^^^^^^
    ...<6 lines>...
    )
    ^
  File "/Users/louisyeo18/telegram_portfolio_bot/venv/lib/python3.13/site-packages/telegram/_bot.py", line 732, in _do_post
    result = await request.post(
             ^^^^^^^^^^^^^^^^^^^
    ...<6 lines>...
    )
    ^
  File "/Users/louisyeo18/telegram_portfolio_bot/venv/lib/python3.13/site-packages/telegram/request/_baserequest.py", line 198, in post
    result = await self._request_wrapper(
             ^^^^^^^^^^^^^^^^^^^^^^^^^^^^
    ...<7 lines>...
    )
    ^
  File "/Users/louisyeo18/telegram_portfolio_bot/venv/lib/python3.13/site-packages/telegram/request/_baserequest.py", line 375, in _request_wrapper
    raise exception
telegram.error.Conflict: Conflict: terminated by other getUpdates request; make sure that only one bot instance is running
No error handlers are registered, logging exception.
Traceback (most recent call last):
  File "/Users/louisyeo18/telegram_portfolio_bot/venv/lib/python3.13/site-packages/telegram/ext/_utils/networkloop.py", line 122, in network_retry_loop
    await do_action()
  File "/Users/louisyeo18/telegram_portfolio_bot/venv/lib/python3.13/site-packages/telegram/ext/_utils/networkloop.py", line 115, in do_action
    action_cb_task.result()
    ~~~~~~~~~~~~~~~~~~~~~^^
  File "/Users/louisyeo18/telegram_portfolio_bot/venv/lib/python3.13/site-packages/telegram/ext/_updater.py", line 340, in polling_action_cb
    updates = await self.bot.get_updates(
              ^^^^^^^^^^^^^^^^^^^^^^^^^^^
    ...<3 lines>...
    )
    ^
  File "/Users/louisyeo18/telegram_portfolio_bot/venv/lib/python3.13/site-packages/telegram/ext/_extbot.py", line 676, in get_updates
    updates = await super().get_updates(
              ^^^^^^^^^^^^^^^^^^^^^^^^^^
    ...<9 lines>...
    )
    ^
  File "/Users/louisyeo18/telegram_portfolio_bot/venv/lib/python3.13/site-packages/telegram/_bot.py", line 4780, in get_updates
    await self._post(
    ^^^^^^^^^^^^^^^^^
    ...<7 lines>...
    ),
    ^
  File "/Users/louisyeo18/telegram_portfolio_bot/venv/lib/python3.13/site-packages/telegram/_bot.py", line 703, in _post
    return await self._do_post(
           ^^^^^^^^^^^^^^^^^^^^
    ...<6 lines>...
    )
    ^
  File "/Users/louisyeo18/telegram_portfolio_bot/venv/lib/python3.13/site-packages/telegram/ext/_extbot.py", line 372, in _do_post
    return await super()._do_post(
           ^^^^^^^^^^^^^^^^^^^^^^^
    ...<6 lines>...
    )
    ^
  File "/Users/louisyeo18/telegram_portfolio_bot/venv/lib/python3.13/site-packages/telegram/_bot.py", line 732, in _do_post
    result = await request.post(
             ^^^^^^^^^^^^^^^^^^^
    ...<6 lines>...
    )
    ^
  File "/Users/louisyeo18/telegram_portfolio_bot/venv/lib/python3.13/site-packages/telegram/request/_baserequest.py", line 198, in post
    result = await self._request_wrapper(
             ^^^^^^^^^^^^^^^^^^^^^^^^^^^^
    ...<7 lines>...
    )
    ^
  File "/Users/louisyeo18/telegram_portfolio_bot/venv/lib/python3.13/site-packages/telegram/request/_baserequest.py", line 375, in _request_wrapper
    raise exception
telegram.error.Conflict: Conflict: terminated by other getUpdates request; make sure that only one bot instance is running
No error handlers are registered, logging exception.
Traceback (most recent call last):
  File "/Users/louisyeo18/telegram_portfolio_bot/venv/lib/python3.13/site-packages/telegram/ext/_utils/networkloop.py", line 122, in network_retry_loop
    await do_action()
  File "/Users/louisyeo18/telegram_portfolio_bot/venv/lib/python3.13/site-packages/telegram/ext/_utils/networkloop.py", line 115, in do_action
    action_cb_task.result()
    ~~~~~~~~~~~~~~~~~~~~~^^
  File "/Users/louisyeo18/telegram_portfolio_bot/venv/lib/python3.13/site-packages/telegram/ext/_updater.py", line 340, in polling_action_cb
    updates = await self.bot.get_updates(
              ^^^^^^^^^^^^^^^^^^^^^^^^^^^
    ...<3 lines>...
    )
    ^
  File "/Users/louisyeo18/telegram_portfolio_bot/venv/lib/python3.13/site-packages/telegram/ext/_extbot.py", line 676, in get_updates
    updates = await super().get_updates(
              ^^^^^^^^^^^^^^^^^^^^^^^^^^
    ...<9 lines>...
    )
    ^
  File "/Users/louisyeo18/telegram_portfolio_bot/venv/lib/python3.13/site-packages/telegram/_bot.py", line 4780, in get_updates
    await self._post(
    ^^^^^^^^^^^^^^^^^
    ...<7 lines>...
    ),
    ^
  File "/Users/louisyeo18/telegram_portfolio_bot/venv/lib/python3.13/site-packages/telegram/_bot.py", line 703, in _post
    return await self._do_post(
           ^^^^^^^^^^^^^^^^^^^^
    ...<6 lines>...
    )
    ^
  File "/Users/louisyeo18/telegram_portfolio_bot/venv/lib/python3.13/site-packages/telegram/ext/_extbot.py", line 372, in _do_post
    return await super()._do_post(
           ^^^^^^^^^^^^^^^^^^^^^^^
    ...<6 lines>...
    )
    ^
  File "/Users/louisyeo18/telegram_portfolio_bot/venv/lib/python3.13/site-packages/telegram/_bot.py", line 732, in _do_post
    result = await request.post(
             ^^^^^^^^^^^^^^^^^^^
    ...<6 lines>...
    )
    ^
  File "/Users/louisyeo18/telegram_portfolio_bot/venv/lib/python3.13/site-packages/telegram/request/_baserequest.py", line 198, in post
    result = await self._request_wrapper(
             ^^^^^^^^^^^^^^^^^^^^^^^^^^^^
    ...<7 lines>...
    )
    ^
  File "/Users/louisyeo18/telegram_portfolio_bot/venv/lib/python3.13/site-packages/telegram/request/_baserequest.py", line 375, in _request_wrapper
    raise exception
telegram.error.Conflict: Conflict: terminated by other getUpdates request; make sure that only one bot instance is running
No error handlers are registered, logging exception.
Traceback (most recent call last):
  File "/Users/louisyeo18/telegram_portfolio_bot/venv/lib/python3.13/site-packages/telegram/ext/_utils/networkloop.py", line 122, in network_retry_loop
    await do_action()
  File "/Users/louisyeo18/telegram_portfolio_bot/venv/lib/python3.13/site-packages/telegram/ext/_utils/networkloop.py", line 115, in do_action
    action_cb_task.result()
    ~~~~~~~~~~~~~~~~~~~~~^^
  File "/Users/louisyeo18/telegram_portfolio_bot/venv/lib/python3.13/site-packages/telegram/ext/_updater.py", line 340, in polling_action_cb
    updates = await self.bot.get_updates(
              ^^^^^^^^^^^^^^^^^^^^^^^^^^^
    ...<3 lines>...
    )
    ^
  File "/Users/louisyeo18/telegram_portfolio_bot/venv/lib/python3.13/site-packages/telegram/ext/_extbot.py", line 676, in get_updates
    updates = await super().get_updates(
              ^^^^^^^^^^^^^^^^^^^^^^^^^^
    ...<9 lines>...
    )
    ^
  File "/Users/louisyeo18/telegram_portfolio_bot/venv/lib/python3.13/site-packages/telegram/_bot.py", line 4780, in get_updates
    await self._post(
    ^^^^^^^^^^^^^^^^^
    ...<7 lines>...
    ),
    ^
  File "/Users/louisyeo18/telegram_portfolio_bot/venv/lib/python3.13/site-packages/telegram/_bot.py", line 703, in _post
    return await self._do_post(
           ^^^^^^^^^^^^^^^^^^^^
    ...<6 lines>...
    )
    ^
  File "/Users/louisyeo18/telegram_portfolio_bot/venv/lib/python3.13/site-packages/telegram/ext/_extbot.py", line 372, in _do_post
    return await super()._do_post(
           ^^^^^^^^^^^^^^^^^^^^^^^
    ...<6 lines>...
    )
    ^
  File "/Users/louisyeo18/telegram_portfolio_bot/venv/lib/python3.13/site-packages/telegram/_bot.py", line 732, in _do_post
    result = await request.post(
             ^^^^^^^^^^^^^^^^^^^
    ...<6 lines>...
    )
    ^
  File "/Users/louisyeo18/telegram_portfolio_bot/venv/lib/python3.13/site-packages/telegram/request/_baserequest.py", line 198, in post
    result = await self._request_wrapper(
             ^^^^^^^^^^^^^^^^^^^^^^^^^^^^
    ...<7 lines>...
    )
    ^
  File "/Users/louisyeo18/telegram_portfolio_bot/venv/lib/python3.13/site-packages/telegram/request/_baserequest.py", line 375, in _request_wrapper
    raise exception
telegram.error.Conflict: Conflict: terminated by other getUpdates request; make sure that only one bot instance is running
No error handlers are registered, logging exception.
Traceback (most recent call last):
  File "/Users/louisyeo18/telegram_portfolio_bot/venv/lib/python3.13/site-packages/telegram/ext/_utils/networkloop.py", line 122, in network_retry_loop
    await do_action()
  File "/Users/louisyeo18/telegram_portfolio_bot/venv/lib/python3.13/site-packages/telegram/ext/_utils/networkloop.py", line 115, in do_action
    action_cb_task.result()
    ~~~~~~~~~~~~~~~~~~~~~^^
  File "/Users/louisyeo18/telegram_portfolio_bot/venv/lib/python3.13/site-packages/telegram/ext/_updater.py", line 340, in polling_action_cb
    updates = await self.bot.get_updates(
              ^^^^^^^^^^^^^^^^^^^^^^^^^^^
    ...<3 lines>...
    )
    ^
  File "/Users/louisyeo18/telegram_portfolio_bot/venv/lib/python3.13/site-packages/telegram/ext/_extbot.py", line 676, in get_updates
    updates = await super().get_updates(
              ^^^^^^^^^^^^^^^^^^^^^^^^^^
    ...<9 lines>...
    )
    ^
  File "/Users/louisyeo18/telegram_portfolio_bot/venv/lib/python3.13/site-packages/telegram/_bot.py", line 4780, in get_updates
    await self._post(
    ^^^^^^^^^^^^^^^^^
    ...<7 lines>...
    ),
    ^
  File "/Users/louisyeo18/telegram_portfolio_bot/venv/lib/python3.13/site-packages/telegram/_bot.py", line 703, in _post
    return await self._do_post(
           ^^^^^^^^^^^^^^^^^^^^
    ...<6 lines>...
    )
    ^
  File "/Users/louisyeo18/telegram_portfolio_bot/venv/lib/python3.13/site-packages/telegram/ext/_extbot.py", line 372, in _do_post
    return await super()._do_post(
           ^^^^^^^^^^^^^^^^^^^^^^^
    ...<6 lines>...
    )
    ^
  File "/Users/louisyeo18/telegram_portfolio_bot/venv/lib/python3.13/site-packages/telegram/_bot.py", line 732, in _do_post
    result = await request.post(
             ^^^^^^^^^^^^^^^^^^^
    ...<6 lines>...
    )
    ^
  File "/Users/louisyeo18/telegram_portfolio_bot/venv/lib/python3.13/site-packages/telegram/request/_baserequest.py", line 198, in post
    result = await self._request_wrapper(
             ^^^^^^^^^^^^^^^^^^^^^^^^^^^^
    ...<7 lines>...
    )
    ^
  File "/Users/louisyeo18/telegram_portfolio_bot/venv/lib/python3.13/site-packages/telegram/request/_baserequest.py", line 375, in _request_wrapper
    raise exception
telegram.error.Conflict: Conflict: terminated by other getUpdates request; make sure that only one bot instance is running
No error handlers are registered, logging exception.
Traceback (most recent call last):
  File "/Users/louisyeo18/telegram_portfolio_bot/venv/lib/python3.13/site-packages/telegram/ext/_utils/networkloop.py", line 122, in network_retry_loop
    await do_action()
  File "/Users/louisyeo18/telegram_portfolio_bot/venv/lib/python3.13/site-packages/telegram/ext/_utils/networkloop.py", line 115, in do_action
    action_cb_task.result()
    ~~~~~~~~~~~~~~~~~~~~~^^
  File "/Users/louisyeo18/telegram_portfolio_bot/venv/lib/python3.13/site-packages/telegram/ext/_updater.py", line 340, in polling_action_cb
    updates = await self.bot.get_updates(
              ^^^^^^^^^^^^^^^^^^^^^^^^^^^
    ...<3 lines>...
    )
    ^
  File "/Users/louisyeo18/telegram_portfolio_bot/venv/lib/python3.13/site-packages/telegram/ext/_extbot.py", line 676, in get_updates
    updates = await super().get_updates(
              ^^^^^^^^^^^^^^^^^^^^^^^^^^
    ...<9 lines>...
    )
    ^
  File "/Users/louisyeo18/telegram_portfolio_bot/venv/lib/python3.13/site-packages/telegram/_bot.py", line 4780, in get_updates
    await self._post(
    ^^^^^^^^^^^^^^^^^
    ...<7 lines>...
    ),
    ^
  File "/Users/louisyeo18/telegram_portfolio_bot/venv/lib/python3.13/site-packages/telegram/_bot.py", line 703, in _post
    return await self._do_post(
           ^^^^^^^^^^^^^^^^^^^^
    ...<6 lines>...
    )
    ^
  File "/Users/louisyeo18/telegram_portfolio_bot/venv/lib/python3.13/site-packages/telegram/ext/_extbot.py", line 372, in _do_post
    return await super()._do_post(
           ^^^^^^^^^^^^^^^^^^^^^^^
    ...<6 lines>...
    )
    ^
  File "/Users/louisyeo18/telegram_portfolio_bot/venv/lib/python3.13/site-packages/telegram/_bot.py", line 732, in _do_post
    result = await request.post(
             ^^^^^^^^^^^^^^^^^^^
    ...<6 lines>...
    )
    ^
  File "/Users/louisyeo18/telegram_portfolio_bot/venv/lib/python3.13/site-packages/telegram/request/_baserequest.py", line 198, in post
    result = await self._request_wrapper(
             ^^^^^^^^^^^^^^^^^^^^^^^^^^^^
    ...<7 lines>...
    )
    ^
  File "/Users/louisyeo18/telegram_portfolio_bot/venv/lib/python3.13/site-packages/telegram/request/_baserequest.py", line 375, in _request_wrapper
    raise exception
telegram.error.Conflict: Conflict: terminated by other getUpdates request; make sure that only one bot instance is running
No error handlers are registered, logging exception.
Traceback (most recent call last):
  File "/Users/louisyeo18/telegram_portfolio_bot/venv/lib/python3.13/site-packages/telegram/ext/_utils/networkloop.py", line 122, in network_retry_loop
    await do_action()
  File "/Users/louisyeo18/telegram_portfolio_bot/venv/lib/python3.13/site-packages/telegram/ext/_utils/networkloop.py", line 115, in do_action
    action_cb_task.result()
    ~~~~~~~~~~~~~~~~~~~~~^^
  File "/Users/louisyeo18/telegram_portfolio_bot/venv/lib/python3.13/site-packages/telegram/ext/_updater.py", line 340, in polling_action_cb
    updates = await self.bot.get_updates(
              ^^^^^^^^^^^^^^^^^^^^^^^^^^^
    ...<3 lines>...
    )
    ^
  File "/Users/louisyeo18/telegram_portfolio_bot/venv/lib/python3.13/site-packages/telegram/ext/_extbot.py", line 676, in get_updates
    updates = await super().get_updates(
              ^^^^^^^^^^^^^^^^^^^^^^^^^^
    ...<9 lines>...
    )
    ^
  File "/Users/louisyeo18/telegram_portfolio_bot/venv/lib/python3.13/site-packages/telegram/_bot.py", line 4780, in get_updates
    await self._post(
    ^^^^^^^^^^^^^^^^^
    ...<7 lines>...
    ),
    ^
  File "/Users/louisyeo18/telegram_portfolio_bot/venv/lib/python3.13/site-packages/telegram/_bot.py", line 703, in _post
    return await self._do_post(
           ^^^^^^^^^^^^^^^^^^^^
    ...<6 lines>...
    )
    ^
  File "/Users/louisyeo18/telegram_portfolio_bot/venv/lib/python3.13/site-packages/telegram/ext/_extbot.py", line 372, in _do_post
    return await super()._do_post(
           ^^^^^^^^^^^^^^^^^^^^^^^
    ...<6 lines>...
    )
    ^
  File "/Users/louisyeo18/telegram_portfolio_bot/venv/lib/python3.13/site-packages/telegram/_bot.py", line 732, in _do_post
    result = await request.post(
             ^^^^^^^^^^^^^^^^^^^
    ...<6 lines>...
    )
    ^
  File "/Users/louisyeo18/telegram_portfolio_bot/venv/lib/python3.13/site-packages/telegram/request/_baserequest.py", line 198, in post
    result = await self._request_wrapper(
             ^^^^^^^^^^^^^^^^^^^^^^^^^^^^
    ...<7 lines>...
    )
    ^
  File "/Users/louisyeo18/telegram_portfolio_bot/venv/lib/python3.13/site-packages/telegram/request/_baserequest.py", line 375, in _request_wrapper
    raise exception
telegram.error.Conflict: Conflict: terminated by other getUpdates request; make sure that only one bot instance is running
No error handlers are registered, logging exception.
Traceback (most recent call last):
  File "/Users/louisyeo18/telegram_portfolio_bot/venv/lib/python3.13/site-packages/telegram/ext/_utils/networkloop.py", line 122, in network_retry_loop
    await do_action()
  File "/Users/louisyeo18/telegram_portfolio_bot/venv/lib/python3.13/site-packages/telegram/ext/_utils/networkloop.py", line 115, in do_action
    action_cb_task.result()
    ~~~~~~~~~~~~~~~~~~~~~^^
  File "/Users/louisyeo18/telegram_portfolio_bot/venv/lib/python3.13/site-packages/telegram/ext/_updater.py", line 340, in polling_action_cb
    updates = await self.bot.get_updates(
              ^^^^^^^^^^^^^^^^^^^^^^^^^^^
    ...<3 lines>...
    )
    ^
  File "/Users/louisyeo18/telegram_portfolio_bot/venv/lib/python3.13/site-packages/telegram/ext/_extbot.py", line 676, in get_updates
    updates = await super().get_updates(
              ^^^^^^^^^^^^^^^^^^^^^^^^^^
    ...<9 lines>...
    )
    ^
  File "/Users/louisyeo18/telegram_portfolio_bot/venv/lib/python3.13/site-packages/telegram/_bot.py", line 4780, in get_updates
    await self._post(
    ^^^^^^^^^^^^^^^^^
    ...<7 lines>...
    ),
    ^
  File "/Users/louisyeo18/telegram_portfolio_bot/venv/lib/python3.13/site-packages/telegram/_bot.py", line 703, in _post
    return await self._do_post(
           ^^^^^^^^^^^^^^^^^^^^
    ...<6 lines>...
    )
    ^
  File "/Users/louisyeo18/telegram_portfolio_bot/venv/lib/python3.13/site-packages/telegram/ext/_extbot.py", line 372, in _do_post
    return await super()._do_post(
           ^^^^^^^^^^^^^^^^^^^^^^^
    ...<6 lines>...
    )
    ^
  File "/Users/louisyeo18/telegram_portfolio_bot/venv/lib/python3.13/site-packages/telegram/_bot.py", line 732, in _do_post
    result = await request.post(
             ^^^^^^^^^^^^^^^^^^^
    ...<6 lines>...
    )
    ^
  File "/Users/louisyeo18/telegram_portfolio_bot/venv/lib/python3.13/site-packages/telegram/request/_baserequest.py", line 198, in post
    result = await self._request_wrapper(
             ^^^^^^^^^^^^^^^^^^^^^^^^^^^^
    ...<7 lines>...
    )
    ^
  File "/Users/louisyeo18/telegram_portfolio_bot/venv/lib/python3.13/site-packages/telegram/request/_baserequest.py", line 375, in _request_wrapper
    raise exception
telegram.error.Conflict: Conflict: terminated by other getUpdates request; make sure that only one bot instance is running
